#VRML_SIM R2023b utf8
# Mecanum Robot


PROTO mecanum [
  field SFVec3f translation -0.0800311 4.77003 0.113416
  field SFRotation rotation 7.912008040846748e-05 0.008580972844108182 0.9999631796446615 0.0004992696677112809
  field SFString name "mecanum"
  field SFString controller "<extern>"
]
{
  Robot {
    translation IS translation
    rotation IS rotation
    children [
      Accelerometer {
      }
      Gyro {
      }
      Compass {
      }
      Solid {
        rotation 0 0 1 1.01503e-06
        name "imu_link"
      }
      GPS {
      }
      InertialUnit {
        name "inertial_unit"
      }
      Lidar {
        translation 0 0 0.23
        rotation 0 0 -1 1.5708
        name "LDS-01"
        horizontalResolution 360
        fieldOfView 6.2832
        numberOfLayers 1
        near 0.07
        minRange 0.8
        maxRange 13
        minFrequency 5
        maxFrequency 10
      }
      SliderJoint {
        jointParameters JointParameters {
          position -1.5538194684342538e-07
        }
        device [
          LinearMotor {
          }
        ]
        endPoint Solid {
          translation -0.2 0 0.3009998446180531
          children [
            Shape {
              appearance PBRAppearance {
                baseColor 0.141176 0.121569 0.192157
                metalness 0
              }
              geometry Box {
                size 0.12 1.2 0.11
              }
            }
          ]
          name "solid(3)"
          boundingObject Box {
            size 0.12 1.2 0.11
          }
          physics Physics {
            density 1
          }
        }
      }
      SliderJoint {
        jointParameters JointParameters {
          position -1.5538194227238503e-07
        }
        device [
          LinearMotor {
          }
        ]
        endPoint Solid {
          translation 0.2 0 0.30099984461805773
          children [
            Shape {
              appearance PBRAppearance {
                baseColor 0.141176 0.121569 0.192157
                metalness 0
              }
              geometry Box {
                size 0.12 1.2 0.11
              }
            }
          ]
          name "solid(2)"
          boundingObject Box {
            size 0.12 1.2 0.11
          }
          physics Physics {
            density 1
          }
        }
      }
      DEF Wheels Group {
        children [
          HingeJoint {
            jointParameters HingeJointParameters {
              anchor -0.35 -0.45 0
            }
            device [
              RotationalMotor {
                name "front_right_motor"
                maxVelocity 100
                maxTorque 100
              }
              PositionSensor {
                name "front_right_wheel_joint_sensor"
              }
            ]
            endPoint Solid {
              translation -0.35 -0.45 0
              rotation 0.5773509358554482 -0.5773489358556706 -0.5773509358554489 2.0943953071795858
              children [
                DEF INTERIOR_WHEEL Group {
                  children [
                    Shape {
                      appearance DEF WHEEL_APPEARANCE PBRAppearance {
                        baseColor 0.381347 0.381347 0.381347
                        metalness 0.4
                        emissiveColor 0.202 0.202 0.202
                      }
                      geometry Mesh {
                        url [
                          "https://raw.githubusercontent.com/cyberbotics/webots/R2023b/projects/robots/robotnik/summit_xl_steel/protos/meshes/omni_wheel_rims_int.dae"
                        ]
                      }
                    }
                    Shape {
                      appearance DEF ROLLERS_APPEARANCE PBRAppearance {
                        baseColor 0.08132 0.08132 0.08132
                        roughness 0.8
                        metalness 0
                      }
                      geometry Mesh {
                        url [
                          "https://raw.githubusercontent.com/cyberbotics/webots/R2023b/projects/robots/robotnik/summit_xl_steel/protos/meshes/omni_wheel_rollers_int.dae"
                        ]
                      }
                    }
                  ]
                }
              ]
              name "front_right_wheel"
              contactMaterial "InteriorWheelMat"
              boundingObject DEF WHEEL_BO Cylinder {
                height 0.08
                radius 0.123
              }
              physics Physics {
                density -1
                mass 6.5
                centerOfMass [
                  0 0 0
                ]
                inertiaMatrix [
                  0.0303095 0.05241925 0.0303095
                  0 0 0
                ]
              }
            }
          }
          HingeJoint {
            jointParameters HingeJointParameters {
              anchor 0.35 -0.45 0
            }
            device [
              RotationalMotor {
                name "front_left_motor"
                maxVelocity 100
                maxTorque 100
              }
              PositionSensor {
                name "front_left_wheel_joint_sensor"
              }
            ]
            endPoint Solid {
              translation 0.35 -0.45 0
              rotation 0.5773509358554486 -0.5773489358556692 -0.5773509358554503 2.094395307179585
              children [
                DEF EXTERIOR_WHEEL Group {
                  children [
                    Shape {
                      appearance DEF WHEEL_APPEARANCE PBRAppearance {
                        baseColor 0.381347 0.381347 0.381347
                        metalness 0.4
                        emissiveColor 0.202 0.202 0.202
                      }
                      geometry Mesh {
                        url [
                          "https://raw.githubusercontent.com/cyberbotics/webots/R2023b/projects/robots/robotnik/summit_xl_steel/protos/meshes/omni_wheel_rims_ext.dae"
                        ]
                      }
                    }
                    Shape {
                      appearance DEF ROLLERS_APPEARANCE PBRAppearance {
                        baseColor 0.08132 0.08132 0.08132
                        roughness 0.8
                        metalness 0
                      }
                      geometry Mesh {
                        url [
                          "https://raw.githubusercontent.com/cyberbotics/webots/R2023b/projects/robots/robotnik/summit_xl_steel/protos/meshes/omni_wheel_rollers_ext.dae"
                        ]
                      }
                    }
                  ]
                }
              ]
              name "front_left_wheel"
              contactMaterial "ExteriorWheelMat"
              boundingObject DEF WHEEL_BO Cylinder {
                height 0.08
                radius 0.123
              }
              physics Physics {
                density -1
                mass 6.5
                centerOfMass [
                  0 0 0
                ]
                inertiaMatrix [
                  0.0303095 0.05241925 0.0303095
                  0 0 0
                ]
              }
            }
          }
          HingeJoint {
            jointParameters HingeJointParameters {
              anchor -0.35 0.45 0
            }
            device [
              RotationalMotor {
                name "back_left_motor"
                maxVelocity 100
                maxTorque 100
              }
              PositionSensor {
                name "back_left_wheel_joint_sensor"
              }
            ]
            endPoint Solid {
              translation 0.34983700000000006 0.45 0
              rotation 0.5773509358554485 -0.5773489358556707 -0.5773509358554486 2.0943953071795853
              children [
                DEF INTERIOR_WHEEL Group {
                  children [
                    Shape {
                      appearance DEF WHEEL_APPEARANCE PBRAppearance {
                        baseColor 0.381347 0.381347 0.381347
                        metalness 0.4
                        emissiveColor 0.202 0.202 0.202
                      }
                      geometry Mesh {
                        url [
                          "https://raw.githubusercontent.com/cyberbotics/webots/R2023b/projects/robots/robotnik/summit_xl_steel/protos/meshes/omni_wheel_rims_int.dae"
                        ]
                      }
                    }
                    Shape {
                      appearance DEF ROLLERS_APPEARANCE PBRAppearance {
                        baseColor 0.08132 0.08132 0.08132
                        roughness 0.8
                        metalness 0
                      }
                      geometry Mesh {
                        url [
                          "https://raw.githubusercontent.com/cyberbotics/webots/R2023b/projects/robots/robotnik/summit_xl_steel/protos/meshes/omni_wheel_rollers_int.dae"
                        ]
                      }
                    }
                  ]
                }
              ]
              name "back_left_wheel"
              contactMaterial "InteriorWheelMat"
              boundingObject DEF WHEEL_BO Cylinder {
                height 0.08
                radius 0.123
              }
              physics Physics {
                density -1
                mass 6.5
                centerOfMass [
                  0 0 0
                ]
                inertiaMatrix [
                  0.0303095 0.05241925 0.0303095
                  0 0 0
                ]
              }
            }
          }
          HingeJoint {
            jointParameters HingeJointParameters {
              position -0.0004533123016833546
              anchor -0.35 0.45 0
            }
            device [
              RotationalMotor {
                name "back_right_motor"
                maxVelocity 100
                maxTorque 100
              }
              PositionSensor {
                name "back_right_wheel_joint_sensor"
              }
            ]
            endPoint Solid {
              translation -0.34999998689988243 0.4500000262002336 5.779731054670202e-05
              rotation 0.5772636762082106 -0.5775234159304347 -0.5772636764794961 2.0941336066744167
              children [
                DEF EXTERIOR_WHEEL Group {
                  children [
                    Shape {
                      appearance DEF WHEEL_APPEARANCE PBRAppearance {
                        baseColor 0.381347 0.381347 0.381347
                        metalness 0.4
                        emissiveColor 0.202 0.202 0.202
                      }
                      geometry Mesh {
                        url [
                          "https://raw.githubusercontent.com/cyberbotics/webots/R2023b/projects/robots/robotnik/summit_xl_steel/protos/meshes/omni_wheel_rims_ext.dae"
                        ]
                      }
                    }
                    Shape {
                      appearance DEF ROLLERS_APPEARANCE PBRAppearance {
                        baseColor 0.08132 0.08132 0.08132
                        roughness 0.8
                        metalness 0
                      }
                      geometry Mesh {
                        url [
                          "https://raw.githubusercontent.com/cyberbotics/webots/R2023b/projects/robots/robotnik/summit_xl_steel/protos/meshes/omni_wheel_rollers_ext.dae"
                        ]
                      }
                    }
                  ]
                }
              ]
              name "back_right_wheel"
              contactMaterial "ExteriorWheelMat"
              boundingObject DEF WHEEL_BO Cylinder {
                height 0.08
                radius 0.123
              }
              physics Physics {
                density -1
                mass 6.5
                centerOfMass [
                  0 0 0
                ]
                inertiaMatrix [
                  0.0303095 0.05241925 0.0303095
                  0 0 0
                ]
              }
            }
          }
        ]
      }
      Solid {
        translation 0 0 0.11
        children [
          Shape {
            appearance PBRAppearance {
            }
            geometry Box {
              size 0.6 1.3 0.17
            }
          }
        ]
        name "solid(1)"
        boundingObject Shape {
          appearance PBRAppearance {
          }
          geometry Box {
            size 0.6 1.3 0.17
          }
        }
        physics Physics {
          density 1
        }
      }
      DEF MainBodyM Solid {
        children [
          DEF BaseBodyM Shape {
            appearance PBRAppearance {
              metalness 0.5
              IBLStrength 0.2
            }
            geometry Box {
              size 0.6 1.3 0.05
            }
          }
        ]
      }
      Solid {
        translation 0 0 0.22
        children [
          DEF TopBodyM Shape {
            appearance PBRAppearance {
              metalness 0
              IBLStrength 0.2
            }
            geometry Box {
              size 0.9 1.3 0.05
            }
          }
        ]
        name "BodyTop"
        boundingObject USE TopBodyM
        physics Physics {
          density -1
          mass 2
        }
      }
    ]
    name IS name
    boundingObject USE BaseBodyM
    physics Physics {
      density -1
      mass 20
    }
    controller IS controller
  }
}
