#VRML_SIM R2023b utf8
# Tracked Robot

PROTO tracked [
  field SFVec3f translation -0.0800311 4.77003 0.113416
  field SFRotation rotation 7.912008040846748e-05 0.008580972844108182 0.9999631796446615 0.0004992696677112809
  field SFString name "tracked"
  field SFString controller "<extern>"
]
{
  Robot {
    translation IS translation
    rotation IS rotation
    children [
      Accelerometer {
      }
      Gyro {
      }
      Compass {
      }
      Solid {
        rotation 0 0 1 1.01503e-06
        name "imu_link"
      }
      GPS {
      }
      InertialUnit {
        name "inertial_unit"
      }
      Lidar {
        translation 0 0 0.23
        rotation 0 0 -1 -1.5708
        name "LDS-01"
        horizontalResolution 360
        fieldOfView 6.2832
        numberOfLayers 1
        near 0.07
        minRange 0.6
        maxRange 13
        minFrequency 5
        maxFrequency 10
      }
      DEF Right_Track Group {
        children [
          HingeJoint {
            jointParameters HingeJointParameters {
              anchor 0.54 -0.6 0
            }
            device [
              RotationalMotor {
                name "rw4m"
                multiplier -1
              }
            ]
            endPoint Solid {
              translation 0.5400013600385571 -0.6001151173795845 -0.00010792732304689403
              rotation 0.7071084935752093 2.135504484968725e-06 0.7071050687905143 3.1415942777436445
              children [
                DEF WheeledRFirstLeftWheel Shape {
                  appearance PBRAppearance {
                    baseColor 0.6 0.756863 0.945098
                    roughness 1
                    metalness 0.7
                  }
                  geometry Cylinder {
                    height 0.08
                    radius 0.2
                  }
                }
              ]
              name "rw4"
              boundingObject USE WheeledRFirstLeftWheel
              physics Physics {
                density -1
                mass 1
              }
            }
          }
          HingeJoint {
            jointParameters HingeJointParameters {
              anchor 0.54 -0.2 0
            }
            device [
              RotationalMotor {
                name "rw3m"
                multiplier -1
              }
            ]
            endPoint Solid {
              translation 0.5400014746058788 -0.2001141207926427 -0.00010881921613119366
              rotation 0.7071084935752093 2.135504484968725e-06 0.7071050687905143 3.1415942777436445
              children [
                DEF WheeledRFirstLeftWheel Shape {
                  appearance PBRAppearance {
                    baseColor 0.6 0.756863 0.945098
                    roughness 1
                    metalness 0.7
                  }
                  geometry Cylinder {
                    height 0.08
                    radius 0.2
                  }
                }
              ]
              name "rw3"
              boundingObject USE WheeledRFirstLeftWheel
              physics Physics {
                density -1
                mass 1
              }
            }
          }
          HingeJoint {
            jointParameters HingeJointParameters {
              anchor 0.54 0.2 0
            }
            device [
              RotationalMotor {
                name "rw2m"
                multiplier -1
              }
            ]
            endPoint Solid {
              translation 0.5400015891732006 0.19988687579450737 -0.00010971110943040822
              rotation -3.024819598070387e-06 0.9999999999908504 -3.024833743188631e-06 4.712388736388545
              children [
                DEF WheeledRFirstLeftWheel Shape {
                  appearance PBRAppearance {
                    baseColor 0.6 0.756863 0.945098
                    roughness 1
                    metalness 0.7
                  }
                  geometry Cylinder {
                    height 0.08
                    radius 0.2
                  }
                }
              ]
              name "rw2"
              boundingObject USE WheeledRFirstLeftWheel
              physics Physics {
                density -1
                mass 1
              }
            }
          }
          HingeJoint {
            jointParameters HingeJointParameters {
              anchor 0.54 0.6 0
            }
            device [
              RotationalMotor {
                name "rw1m"
                multiplier -1
              }
            ]
            endPoint Solid {
              translation 0.5400017037405229 0.5998878723812407 -0.000110603002300218
              rotation 0.7071084935752093 2.135504484968725e-06 0.7071050687905143 3.1415942777436445
              children [
                DEF WheeledRFirstLeftWheel Shape {
                  appearance PBRAppearance {
                    baseColor 0.6 0.756863 0.945098
                    roughness 1
                    metalness 0.7
                  }
                  geometry Cylinder {
                    height 0.08
                    radius 0.2
                  }
                }
              ]
              name "rw1"
              boundingObject USE WheeledRFirstLeftWheel
              physics Physics {
                density -1
                mass 1
              }
            }
          }
        ]
      }
      DEF Left_Track Group {
        children [
          HingeJoint {
            jointParameters HingeJointParameters {
              anchor -0.54 -0.6 0
            }
            device [
              RotationalMotor {
                name "lw4m"
                multiplier -1
              }
            ]
            endPoint Solid {
              translation -0.5399986709509977 -0.6001153088284572 -0.00010768153122407288
              rotation 0.7071084935752093 2.135504484968725e-06 0.7071050687905143 3.1415942777436445
              children [
                DEF WheeledRFirstLeftWheel Shape {
                  appearance PBRAppearance {
                    baseColor 0.6 0.756863 0.945098
                    roughness 1
                    metalness 0.7
                  }
                  geometry Cylinder {
                    height 0.08
                    radius 0.2
                  }
                }
              ]
              name "lw4"
              boundingObject USE WheeledRFirstLeftWheel
              physics Physics {
                density -1
                mass 1
              }
            }
          }
          HingeJoint {
            jointParameters HingeJointParameters {
              anchor -0.54 -0.2 0
            }
            device [
              RotationalMotor {
                name "lw3m"
                multiplier -1
              }
            ]
            endPoint Solid {
              translation -0.5399985563836759 -0.20011431224151538 -0.00010857342430857186
              rotation 0.7071084935752093 2.135504484968725e-06 0.7071050687905143 3.1415942777436445
              children [
                DEF WheeledRFirstLeftWheel Shape {
                  appearance PBRAppearance {
                    baseColor 0.6 0.756863 0.945098
                    roughness 1
                    metalness 0.7
                  }
                  geometry Cylinder {
                    height 0.08
                    radius 0.2
                  }
                }
              ]
              name "lw3"
              boundingObject USE WheeledRFirstLeftWheel
              physics Physics {
                density -1
                mass 1
              }
            }
          }
          HingeJoint {
            jointParameters HingeJointParameters {
              anchor -0.54 0.2 0
            }
            device [
              RotationalMotor {
                name "lw2m"
                multiplier -1
              }
            ]
            endPoint Solid {
              translation -0.539998441816354 0.19988668434542634 -0.00010946531739309722
              rotation 0.7071084935752093 2.135504484968725e-06 0.7071050687905143 3.1415942777436445
              children [
                DEF WheeledRFirstLeftWheel Shape {
                  appearance PBRAppearance {
                    baseColor 0.6 0.756863 0.945098
                    roughness 1
                    metalness 0.7
                  }
                  geometry Cylinder {
                    height 0.08
                    radius 0.2
                  }
                }
              ]
              name "lw2"
              boundingObject USE WheeledRFirstLeftWheel
              physics Physics {
                density -1
                mass 1
              }
            }
          }
          HingeJoint {
            jointParameters HingeJointParameters {
              anchor -0.54 0.6 0
            }
            device [
              RotationalMotor {
                name "lw1m"
                multiplier -1
              }
            ]
            endPoint Solid {
              translation -0.539998327249032 0.5998876809323682 -0.0001103572104774137
              rotation 0.7071084935752093 2.135504484968725e-06 0.7071050687905143 3.1415942777436445
              children [
                DEF WheeledRFirstLeftWheel Shape {
                  appearance PBRAppearance {
                    baseColor 0.6 0.756863 0.945098
                    roughness 1
                    metalness 0.7
                  }
                  geometry Cylinder {
                    height 0.08
                    radius 0.2
                  }
                }
              ]
              name "lw1"
              boundingObject USE WheeledRFirstLeftWheel
              physics Physics {
                density -1
                mass 1
              }
            }
          }
        ]
      }
      Solid {
        children [
          DEF BaseBody Shape {
            appearance PBRAppearance {
              baseColor 0.239216 0.219608 0.27451
              metalness 0
              IBLStrength 0.2
            }
            geometry Box {
              size 1 1.4 0.05
            }
          }
        ]
        boundingObject USE BaseBody
      }
    ]
    name IS name
    boundingObject USE BaseBody
    physics Physics {
      density -1
      mass 20
    }
    controller IS controller
  }
}
